Workbook

Sheet 기존
B6: 기존 | I6: 처리 | J6: 동시 | K6: 대당
B7: 공병트럭 | E7: 공차트럭 | H7: 상차(1h) | I7: 12대 | J7: 4대 | K7: 20분 | Q7: 기존안 | S7: 개선안
B8: 입차대기 | C8: 8 | E8: 입차대기 | F8: 12 | H8: 하차(1h) | I8: 8대 | J8: 1대 | K8: =60/8 -> 7.5 | Q8: 공병 7대 먼저 | S8: 공병+공차 섞어
B9: 검수(공병하차대기) | C9: 5 | E9: 검수(공병하차대기) | F9: 0 | Q9: 이후 공차 4대 | S9: 12대
B10: 이동 | C10: 2 | E10: 이동 | F10: 0 | Q10: 이후 공병 1대
B11: 공병하차 | C11: 8 | E11: 공병하차 | F11: 0 | H11: 배차간격 | I11: 5분
B12: 이동 | C12: 3 | E12: 이동 | F12: 2 | I12: 이후
B13: 제품상차 | C13: 15 | E13: 제품상차 | F13: 17 | I13: 10분
B14: 이동 | C14: 3 | E14: 이동 | F14: 4
B15: 선전품상차 | C15: 5 | E15: 선전품상차 | F15: 5
B16: 이동 | C16: 2 | E16: 이동 | F16: 1
B17: CO2 | C17: 5 | E17: CO2 | F17: 4
B18: 출하캐노피 | C18: 2 | E18: 출하캐노피 | F18: 3
B19: 출고검사 및 전표 | C19: 5 | E19: 출고검사 및 전표 | F19: 3
B20: total | C20: =SUM(C8:C19) -> 63 | E20: total | F20: =SUM(F8:F19) -> 51
B21: 입차대기 제외 | C21: =SUM(C9:C19) -> 55 | E21: 입차대기 제외 | F21: =SUM(F9:F19) -> 39
W22: 공병 | X22: 공차
J23: 끝나는 시간 기준임 | W23: 상차 공통
J24: 1 | K24: 2 | L24: 3 | M24: 4 | N24: 5 | O24: 6 | P24: 7 | Q24: 1 | R24: 2 | S24: 3 | T24: 4 | U24: 8 | W24: 12
G25: 공병 | I25: 입차 | J25: 0.375 | K25: 0.37847222 | L25: 0.38194444 | M25: 0.38541667 | N25: 0.38888889 | O25: 0.39236111 | P25: 0.39583333 | Q25: 0.39930556 | R25: 0.40277778 | S25: 0.40625 | T25: 0.40972222 | U25: 0.41319444 | W25: 23
G26: 검수(공병하차대기) | H26: 0.0034722222 | I26: 검수(공병하차대기) | J26: =J25+$H26 -> 0.37847222 | K26: =J26+$H26 -> 0.38194444 | L26: =K26+$H26 -> 0.38541667 | M26: =L26+$H26 -> 0.38888889 | N26: =M26+$H26 -> 0.39236111 | O26: =N26+$H26 -> 0.39583333 | P26: =O26+$H26 -> 0.39930556 | Q26: =P26+$H38 -> 0.40277778 | R26: =Q26+$H38 -> 0.40625 | S26: =R26+$H38 -> 0.40972222 | T26: =S26+$H38 -> 0.41319444 | U26: =T26+$H26 -> 0.41666667 | W26: 34 | X26: 12
G27: 이동 | H27: 0.0013888889 | I27: 이동 | J27: =J26+$H27 -> 0.37986111 | K27: =K26+$H27 -> 0.38333333 | L27: =L26+$H27 -> 0.38680556 | M27: =M26+$H27 -> 0.39027778 | N27: =N26+$H27 -> 0.39375 | O27: =O26+$H27 -> 0.39722222 | P27: =P26+$H27 -> 0.40069444 | Q27: =Q26+$H39 -> 0.40277778 | R27: =R26+$H39 -> 0.40625 | S27: =S26+$H39 -> 0.40972222 | T27: =T26+$H39 -> 0.41319444 | U27: =U26+$H27 -> 0.41805556 | W27: 45 | X27: 12
G28: 공병하차 | H28: 0.0055555556 | I28: 공병하차 | J28: =J27+$H28 -> 0.38541667 | K28: =J28+$H28 -> 0.39097222 | L28: =K28+$H28 -> 0.39652778 | M28: =L28+$H28 -> 0.40208333 | N28: =M28+$H28 -> 0.40763889 | O28: =N28+$H28 -> 0.41319444 | P28: =O28+$H28 -> 0.41875 | Q28: =Q27+$H40 -> 0.40277778 | R28: =R27+$H40 -> 0.40625 | S28: =S27+$H40 -> 0.40972222 | T28: =T27+$H40 -> 0.41319444 | U28: =P28+$H28 -> 0.42430556 | W28: 5 | X28: 123
G29: 이동 | H29: 0.0020833333 | I29: 이동 | J29: =J28+$H29 -> 0.3875 | K29: =K28+$H29 -> 0.39305556 | L29: =L28+$H29 -> 0.39861111 | M29: =M28+$H29 -> 0.40416667 | N29: =N28+$H29 -> 0.40972222 | O29: =O28+$H29 -> 0.41527778 | P29: =P28+$H29 -> 0.42083333 | Q29: =Q28+$H41 -> 0.40416667 | R29: =R28+$H41 -> 0.40763889 | S29: =S28+$H41 -> 0.41111111 | T29: =Q30+$H41 -> 0.41736111 | U29: =U28+$H29 -> 0.42638889 | W29: 56 | X29: 23
G30: 제품상차 | H30: 0.010416667 | I30: 제품상차 | J30: =J29+$H30 -> 0.39791667 | K30: =K29+$H30 -> 0.40347222 | L30: =L29+$H30 -> 0.40902778 | M30: =M29+$H30 -> 0.41458333 | N30: =N29+$H30 -> 0.42013889 | O30: =O29+$H30 -> 0.42569444 | P30: =P29+$H30 -> 0.43125 | Q30: =Q29+$H42 -> 0.41597222 | R30: =R29+$H42 -> 0.41944444 | S30: =M30+$H42 -> 0.42638889 | T30: =R30+$H42 -> 0.43125 | U30: =U29+$H30 -> 0.43680556 | W30: 56 | X30: 34
G31: 이동 | H31: 0.0020833333 | I31: 이동 | J31: =J30+$H31 -> 0.4 | K31: =K30+$H31 -> 0.40555556 | L31: =L30+$H31 -> 0.41111111 | M31: =M30+$H31 -> 0.41666667 | N31: =N30+$H31 -> 0.42222222 | O31: =O30+$H31 -> 0.42777778 | P31: =P30+$H31 -> 0.43333333 | Q31: =Q30+$H43 -> 0.41875 | R31: =R30+$H43 -> 0.42222222 | S31: =S30+$H43 -> 0.42916667 | T31: =T30+$H43 -> 0.43402778 | U31: =U30+$H31 -> 0.43888889 | W31: 67 | X31: 34
G32: 선전품상차 | H32: 0.0034722222 | I32: 선전품상차 | J32: =J31+$H32 -> 0.40347222 | K32: =K31+$H32 -> 0.40902778 | L32: =L31+$H32 -> 0.41458333 | M32: =M31+$H32 -> 0.42013889 | N32: =R32+$H32 -> 0.43055556 | O32: =N32+$H32 -> 0.43402778 | P32: =S32+$H32 -> 0.44097222 | Q32: =M32+$H44 -> 0.42361111 | R32: =Q32+$H44 -> 0.42708333 | S32: =O32+$H44 -> 0.4375 | T32: =P32+$H44 -> 0.44444444 | U32: =T32+$H32 -> 0.44791667 | W32: 678 | X32: 4
G33: 이동 | H33: 0.0013888889 | I33: 이동 | J33: =J32+$H33 -> 0.40486111 | K33: =K32+$H33 -> 0.41041667 | L33: =L32+$H33 -> 0.41597222 | M33: =M32+$H33 -> 0.42152778 | N33: =N32+$H33 -> 0.43194444 | O33: =O32+$H33 -> 0.43541667 | P33: =P32+$H33 -> 0.44236111 | Q33: =Q32+$H45 -> 0.42430556 | R33: =R32+$H45 -> 0.42777778 | S33: =S32+$H45 -> 0.43819444 | T33: =T32+$H45 -> 0.44513889 | U33: =U32+$H33 -> 0.44930556
G34: CO2 | H34: 0.0034722222 | I34: CO2 | J34: =J33+$H34 -> 0.40833333 | K34: =K33+$H34 -> 0.41388889 | L34: =L33+$H34 -> 0.41944444 | M34: =M33+$H34 -> 0.425 | N34: =N33+$H34 -> 0.43541667 | O34: =O33+$H34 -> 0.43888889 | P34: =P33+$H34 -> 0.44583333 | Q34: =M34+$H46 -> 0.42777778 | R34: =R33+$H46 -> 0.43055556 | S34: =O34+$H46 -> 0.44166667 | T34: =P34+$H46 -> 0.44861111 | U34: =U33+$H34 -> 0.45277778 | W34: 선전품 순서
G35: 출하캐노피 | H35: 0.0013888889 | I35: 출하캐노피 | J35: =J34+$H35 -> 0.40972222 | K35: =K34+$H35 -> 0.41527778 | L35: =L34+$H35 -> 0.42083333 | M35: =M34+$H35 -> 0.42638889 | N35: =N34+$H35 -> 0.43680556 | O35: =O34+$H35 -> 0.44027778 | P35: =P34+$H35 -> 0.44722222 | Q35: =Q34+$H47 -> 0.42986111 | R35: =R34+$H47 -> 0.43263889 | S35: =S34+$H47 -> 0.44375 | T35: =T34+$H47 -> 0.45069444 | U35: =U34+$H35 -> 0.45416667 | W35: 1
G36: 출고검사 및 전표 | H36: 0.0034722222 | I36: 출고검사 및 전표 | J36: =J35+$H36 -> 0.41319444 | K36: =K35+$H36 -> 0.41875 | L36: =L35+$H36 -> 0.42430556 | M36: =M35+$H36 -> 0.42986111 | N36: =N35+$H36 -> 0.44027778 | O36: =O35+$H36 -> 0.44375 | P36: =P35+$H36 -> 0.45069444 | Q36: =Q35+$H48 -> 0.43194444 | R36: =R35+$H48 -> 0.43472222 | S36: =S35+$H48 -> 0.44583333 | T36: =T35+$H48 -> 0.45277778 | U36: =U35+$H36 -> 0.45763889 | W36: 2
G37: 공차 | I37: 소요시간 | J37: =J36-J25 -> 0.038194444 | K37: =K36-K25 -> 0.040277778 | L37: =L36-L25 -> 0.042361111 | M37: =M36-M25 -> 0.044444444 | N37: =N36-N25 -> 0.051388889 | O37: =O36-O25 -> 0.051388889 | P37: =P36-P25 -> 0.054861111 | Q37: =Q36-Q25 -> 0.032638889 | ... U37: =U36-U25 -> 0.044444444 | W37: 3
G38: 검수(공병하차대기) | H38: 0.0034722222 | I38: 평균소요시간 | J38: =AVERAGE(J37:U37) -> 0.042881944 | W38: 4
G39: 이동 | H39: 0 | I39: 공차평균소요시간 | J39: =AVERAGE(Q37:T37) -> 0.036805556 | X39: 1
G40: 공병하차 | H40: 0 | I40: 공병평균소요시간 | J40: =AVERAGE(J37:P37,U37) -> 0.045920139 | X40: 2
G41: 이동 | H41: 0.0013888889 | I41: MAX time | J41: =MAX(J37:U37) -> 0.054861111 | W41: 5
G42: 제품상차 | H42: 0.011805556 | I42: MIN time | J42: =MIN(J37:U37) -> 0.031944444 | W42: 6
G43: 이동 | H43: 0.0027777778 | I43: 공차 MAX time | J43: =MAX(Q37:T37) -> 0.043055556 | X43: 3
G44: 선전품상차 | H44: 0.0034722222 | I44: 공차 MIN time | J44: =MIN(Q37:T37) -> 0.031944444 | W44: 7
G45: 이동 | H45: 0.00069444444 | I45: 공병 MAX time | J45: =MAX(J37:P37,U37) -> 0.054861111 | X45: 4
...

Sheet 개선
I5: 처리 | J5: 동시 | K5: 대당
B6: 개선 : 공차 공병하차 대기 제외 | H6: 상차(1h) | I6: 12대 | J6: 4대 | K6: 20분 | Q6: 기존안 | S6: 개선안
B7: 공병트럭 | E7: 공차트럭 | H7: 하차(1h) | I7: 8대 | J7: 1대 | K7: =60/8 -> 7.5 | Q7: 공병 7대 먼저 | S7: 공병+공차 섞어
B8: 입차대기 | C8: 8 | E8: 입차대기 | F8: 12 | Q8: 이후 공차 4대 | S8: 12대
B9: 검수(공병하차대기) | C9: 5 | E9: 검수(공병하차대기) | F9: 0 | Q9: 이후 공병 1대
B10: 이동 | C10: 2 | E10: 이동 | F10: 0 | H10: 배차간격 | I10: 5분
B11: 공병하차 | C11: 8 | E11: 공병하차 | F11: 0 | I11: 이후
B12: 이동 | C12: 3 | E12: 이동 | F12: 2 | I12: 10분
B13: 제품상차 | C13: 15 | E13: 제품상차 | F13: 17
B14: 이동 | C14: 3 | E14: 이동 | F14: 4
B15: 선전품상차 | C15: 5 | E15: 선전품상차 | F15: 5
B16: 이동 | C16: 2 | E16: 이동 | F16: 1
B17: CO2 | C17: 5 | E17: CO2 | F17: 4
B18: 출하캐노피 | C18: 2 | E18: 출하캐노피 | F18: 3
B19: 출고검사 및 전표 | C19: 5 | E19: 출고검사 및 전표 | F19: 3
B20: total | C20: =SUM(C8:C19) -> 63 | E20: total | F20: =SUM(F8:F19) -> 51
B21: 입차대기 제외 | C21: =SUM(C9:C19) -> 55 | E21: 입차대기 제외 | F21: =SUM(F9:F19) -> 39
W22: 공병 | X22: 공차
J23: 끝나는 시간 기준임 | W23: 상차 공통
J24: 1 | K24: 2 | L24: 3 | M24: 4 | N24: 5 | O24: 6 | P24: 7 | Q24: 1 | R24: 2 | S24: 3 | T24: 4 | U24: 8 | W24: 12
I25: 입차 | J25: 0.375 | K25: 0.37847222 | L25: 0.38194444 | M25: 0.38541667 | N25: 0.38888889 | O25: 0.39236111 | P25: 0.39583333 | Q25: 0.39930556 | R25: 0.40277778 | S25: 0.40625 | T25: 0.40972222 | U25: 0.41319444 | W25: 23 | X25: 1
G26: 검수(공병하차대기) | H26: 0.0034722222 | I26: 검수(공병하차대기) | J26: =J25+$H26 -> 0.37847222 | K26: =K25+$H26 -> 0.38194444 | L26: =L25+$H26 -> 0.38541667 | M26: =M25+$H26 -> 0.38888889 | N26: =N25+$H26 -> 0.39236111 | O26: =O25+$H26 -> 0.39583333 | P26: =P25+$H26 -> 0.39930556 | Q26: =Q25+$H38 -> 0.39930556 | R26: =R25+$H38 -> 0.40277778 | S26: =S25+$H38 -> 0.40625 | T26: =T25+$H38 -> 0.40972222 | U26: =U25+$H26 -> 0.41666667 | W26: 34 | X26: 12
G27: 이동 | H27: 0.0013888889 | I27: 이동 | J27: =J26+$H27 -> 0.37986111 | K27: =K26+$H27 -> 0.38333333 | L27: =L26+$H27 -> 0.38680556 | M27: =M26+$H27 -> 0.39027778 | N27: =N26+$H27 -> 0.39375 | O27: =O26+$H27 -> 0.39722222 | P27: =P26+$H27 -> 0.40069444 | Q27: =Q26+$H39 -> 0.39930556 | R27: =R26+$H39 -> 0.40277778 | S27: =S26+$H39 -> 0.40625 | T27: =T26+$H39 -> 0.40972222 | U27: =U26+$H27 -> 0.41805556 | W27: 4 | X27: 123
G28: 공병하차 | H28: 0.0055555556 | I28: 공병하차 | J28: =J27+$H28 -> 0.38541667 | K28: =J28+$H28 -> 0.39097222 | L28: =K28+$H28 -> 0.39652778 | M28: =L28+$H28 -> 0.40208333 | N28: =M28+$H28 -> 0.40763889 | O28: =N28+$H28 -> 0.41319444 | P28: =O28+$H28 -> 0.41875 | Q28: =Q27+$H40 -> 0.39930556 | R28: =R27+$H40 -> 0.40277778 | S28: =S27+$H40 -> 0.40625 | T28: =T27+$H40 -> 0.40972222 | U28: =P28+$H28 -> 0.42430556 | W28: 45 | X28: 23
G29: 이동 | H29: 0.0020833333 | I29: 이동 | J29: =J28+$H29 -> 0.3875 | K29: =K28+$H29 -> 0.39305556 | L29: =L28+$H29 -> 0.39861111 | M29: =M28+$H29 -> 0.40416667 | N29: =N28+$H29 -> 0.40972222 | O29: =O28+$H29 -> 0.41527778 | P29: =P28+$H29 -> 0.42083333 | Q29: =Q28+$H41 -> 0.40069444 | R29: =R28+$H41 -> 0.40416667 | S29: =S28+$H41 -> 0.40763889 | T29: =T28+$H41 -> 0.41111111 | U29: =U28+$H29 -> 0.42638889 | W29: 5 | X29: 234
G30: 제품상차 | H30: 0.010416667 | I30: 제품상차 | J30: =J29+$H30 -> 0.39791667 | K30: =K29+$H30 -> 0.40347222 | L30: =L29+$H30 -> 0.40902778 | M30: =M29+$H30 -> 0.41458333 | N30: =Q30+$H30 -> 0.42291667 | O30: =O29+$H30 -> 0.42569444 | P30: =P29+$H30 -> 0.43125 | Q30: =Q29+$H42 -> 0.4125 | R30: =R29+$H42 -> 0.41597222 | S30: =L30+$H42 -> 0.42083333 | T30: =M30+$H42 -> 0.42638889 | U30: =U29+$H30 -> 0.43680556 | W30: 56 | X30: 34
G31: 이동 | H31: 0.0020833333 | I31: 이동 | J31: =J30+$H31 -> 0.4 | K31: =K30+$H31 -> 0.40555556 | L31: =L30+$H31 -> 0.41111111 | M31: =M30+$H31 -> 0.41666667 | N31: =N30+$H31 -> 0.425 | O31: =O30+$H31 -> 0.42777778 | P31: =P30+$H31 -> 0.43333333 | Q31: =Q30+$H43 -> 0.41527778 | R31: =R30+$H43 -> 0.41875 | S31: =S30+$H43 -> 0.42361111 | T31: =T30+$H43 -> 0.42916667 | U31: =U30+$H31 -> 0.43888889 | W31: 567 | X31: 4
G32: 선전품상차 | H32: 0.0034722222 | I32: 선전품상차 | J32: =J31+$H32 -> 0.40347222 | K32: =K31+$H32 -> 0.40902778 | L32: =L31+$H32 -> 0.41458333 | M32: =Q32+$H32 -> 0.42222222 | N32: =S32+$H32 -> 0.43263889 | O32: =N32+$H32 -> 0.43611111 | P32: =T32+$H32 -> 0.44305556 | Q32: =Q31+$H44 -> 0.41875 | R32: =M32+$H44 -> 0.42569444 | S32: =R32+$H44 -> 0.42916667 | T32: =O32+$H44 -> 0.43958333 | U32: =P32+$H32 -> 0.44652778 | W32: 678 | X32: 4
G33: 이동 | H33: 0.0013888889 | I33: 이동 | J33: =J32+$H33 -> 0.40486111 | K33: =K32+$H33 -> 0.41041667 | L33: =L32+$H33 -> 0.41597222 | M33: =M32+$H33 -> 0.42361111 | N33: =N32+$H33 -> 0.43402778 | O33: =O32+$H33 -> 0.4375 | P33: =P32+$H33 -> 0.44444444 | Q33: =Q32+$H45 -> 0.41944444 | R33: =R32+$H45 -> 0.42638889 | S33: =S32+$H45 -> 0.42986111 | T33: =T32+$H45 -> 0.44027778 | U33: =U32+$H33 -> 0.44791667
G34: CO2 | H34: 0.0034722222 | I34: CO2 | J34: =J33+$H34 -> 0.40833333 | K34: =K33+$H34 -> 0.41388889 | L34: =L33+$H34 -> 0.41944444 | M34: =M33+$H34 -> 0.42708333 | N34: =N33+$H34 -> 0.4375 | O34: =O33+$H34 -> 0.44097222 | P34: =P33+$H34 -> 0.44791667 | Q34: =Q33+$H46 -> 0.42222222 | R34: =M34+$H46 -> 0.42986111 | S34: =S33+$H46 -> 0.43263889 | T34: =O34+$H46 -> 0.44375 | U34: =U33+$H34 -> 0.45138889 | W34: 선전품 순서
G35: 출하캐노피 | H35: 0.0013888889 | I35: 출하캐노피 | J35: =J34+$H35 -> 0.40972222 | K35: =K34+$H35 -> 0.41527778 | L35: =L34+$H35 -> 0.42083333 | M35: =M34+$H35 -> 0.42847222 | N35: =N34+$H35 -> 0.43888889 | O35: =O34+$H35 -> 0.44236111 | P35: =P34+$H35 -> 0.44930556 | Q35: =Q34+$H47 -> 0.42430556 | R35: =R34+$H47 -> 0.43194444 | S35: =S34+$H47 -> 0.43472222 | T35: =T34+$H47 -> 0.44583333 | U35: =U34+$H35 -> 0.45277778 | W35: 1
G36: 출고검사 및 전표 | H36: 0.0034722222 | I36: 출고검사 및 전표 | J36: =J35+$H36 -> 0.41319444 | K36: =K35+$H36 -> 0.41875 | L36: =L35+$H36 -> 0.42430556 | M36: =M35+$H36 -> 0.43194444 | N36: =N35+$H36 -> 0.44236111 | O36: =O35+$H36 -> 0.44583333 | P36: =P35+$H36 -> 0.45277778 | Q36: =Q35+$H48 -> 0.42638889 | R36: =R35+$H48 -> 0.43402778 | S36: =S35+$H48 -> 0.43680556 | T36: =T35+$H48 -> 0.44791667 | U36: =U35+$H36 -> 0.45625 | W36: 2
I37: 소요시간 | J37: =J36-J25 -> 0.038194444 | K37: =K36-K25 -> 0.040277778 | L37: =L36-L25 -> 0.042361111 | M37: =M36-M25 -> 0.046527778 | N37: =N36-N25 -> 0.053472222 | O37: =O36-O25 -> 0.053472222 | P37: =P36-P25 -> 0.056944444 | Q37: =Q36-Q25 -> 0.027083333 | ... U37: =U36-U25 -> 0.043055556 | W37: 3
G38: 검수(공병하차대기) | H38: 0 | I38: 평균소요시간 | J38: =AVERAGE(J37:U37) -> 0.041782407 | X38: 1
G39: 이동 | H39: 0 | I39: 공차평균소요시간 | J39: =AVERAGE(Q37:T37) -> 0.031770833 | W39: 4
G40: 공병하차 | H40: 0 | I40: 공병평균소요시간 | J40: =AVERAGE(J37:P37,U37) -> 0.046788194 | X40: 2
G41: 이동 | H41: 0.0013888889 | I41: MAX time | J41: =MAX(J37:U37) -> 0.056944444 | X41: 3
G42: 제품상차 | H42: 0.011805556 | I42: MIN time | J42: =MIN(J37:U37) -> 0.027083333 | W42: 5
G43: 이동 | H43: 0.0027777778 | I43: 공차 MAX time | J43: =MAX(Q37:T37) -> 0.038194444 | W43: 6
G44: 선전품상차 | H44: 0.0034722222 | I44: 공차 MIN time | J44: =MIN(Q37:T37) -> 0.027083333 | X44: 4
...

Sheet 개선2
I5: 처리 | J5: 동시 | K5: 대당
B6: 개선 : 공차 공병하차 대기 제외+순서변경 | H6: 상차(1h) | I6: 12대 | J6: 4대 | K6: 20분 | Q6: 기존안 | S6: 개선안
B7: 공병트럭 | E7: 공차트럭 | H7: 하차(1h) | I7: 8대 | J7: 1대 | K7: =60/8 -> 7.5 | Q7: 공병 7대 먼저 | S7: 공병+공차 섞어
B8: 입차대기 | C8: 8 | E8: 입차대기 | F8: 12 | Q8: 이후 공차 4대 | S8: 12대
B9: 검수(공병하차대기) | C9: 5 | E9: 검수(공병하차대기) | F9: 0 | Q9: 이후 공병 1대
B10: 이동 | C10: 2 | E10: 이동 | F10: 0 | H10: 배차간격 | I10: 5분
B11: 공병하차 | C11: 8 | E11: 공병하차 | F11: 0 | I11: 이후
B12: 이동 | C12: 3 | E12: 이동 | F12: 2 | I12: 10분
B13: 제품상차 | C13: 15 | E13: 제품상차 | F13: 17
B14: 이동 | C14: 3 | E14: 이동 | F14: 4
B15: 선전품상차 | C15: 5 | E15: 선전품상차 | F15: 5
B16: 이동 | C16: 2 | E16: 이동 | F16: 1
B17: CO2 | C17: 5 | E17: CO2 | F17: 4
B18: 출하캐노피 | C18: 2 | E18: 출하캐노피 | F18: 3
B19: 출고검사 및 전표 | C19: 5 | E19: 출고검사 및 전표 | F19: 3
B20: total | C20: =SUM(C8:C19) -> 63 | E20: total | F20: =SUM(F8:F19) -> 51
B21: 입차대기 제외 | C21: =SUM(C9:C19) -> 55 | E21: 입차대기 제외 | F21: =SUM(F9:F19) -> 39
W22: 공병 | X22: 공차
J23: 끝나는 시간 기준임 | W23: 상차 공통
J24: 1 | K24: 2 | L24: 1 | M24: 3 | N24: 4 | O24: 2 | P24: 5 | Q24: 6 | R24: 3 | S24: 7 | T24: 8 | U24: 4 | W24: 12 | X24: 12
I25: 입차 | J25: 0.375 | K25: 0.37847222 | L25: 0.38194444 | M25: 0.38541667 | N25: 0.38888889 | O25: 0.39236111 | P25: 0.39583333 | Q25: 0.39930556 | R25: 0.40277778 | S25: 0.40625 | T25: 0.40972222 | U25: 0.41319444 | W25: 123 | X25: 2
G26: 검수(공병하차대기) | H26: 0.0034722222 | I26: 검수(공병하차대기) | J26: =J25+$H26 -> 0.37847222 | K26: =K25+$H26 -> 0.38194444 | L26: =L25+$H38 -> 0.38194444 | M26: =M25+$H26 -> 0.38888889 | N26: =N25+$H26 -> 0.39236111 | O26: =O25+$H38 -> 0.39236111 | P26: =P25+$H26 -> 0.39930556 | Q26: =Q25+$H26 -> 0.40277778 | R26: =R25+$H38 -> 0.40277778 | S26: =S25+$H26 -> 0.40972222 | T26: =T25+$H26 -> 0.41319444 | U26: =U25+$H38 -> 0.41319444 | W26: 234 | X26: 2
G27: 이동 | H27: 0.0013888889 | I27: 이동 | J27: =J26+$H27 -> 0.37986111 | K27: =K26+$H27 -> 0.38333333 | L27: =L26+$H39 -> 0.38194444 | M27: =M26+$H27 -> 0.39027778 | N27: =N26+$H27 -> 0.39375 | O27: =O26+$H39 -> 0.39236111 | P27: =P26+$H27 -> 0.40069444 | Q27: =Q26+$H27 -> 0.40416667 | R27: =R26+$H39 -> 0.40277778 | S27: =S26+$H27 -> 0.41111111 | T27: =T26+$H27 -> 0.41458333 | U27: =U26+$H39 -> 0.41319444 | W27: 34 | X27: 23
G28: 공병하차 | H28: 0.0055555556 | I28: 공병하차 | J28: =J27+$H28 -> 0.38541667 | K28: =K27+$H28 -> 0.38888889 | L28: =L27+$H40 -> 0.38194444 | M28: =M27+$H28 -> 0.39583333 | N28: =N27+$H28 -> 0.39930556 | O28: =O27+$H40 -> 0.39236111 | P28: =P27+$H28 -> 0.40625 | Q28: =Q27+$H28 -> 0.40972222 | R28: =R27+$H40 -> 0.40277778 | S28: =S27+$H28 -> 0.41666667 | T28: =T27+$H28 -> 0.42013889 | U28: =U27+$H40 -> 0.41319444 | W28: 345 | X28: 3
G29: 이동 | H29: 0.0020833333 | I29: 이동 | J29: =J28+$H29 -> 0.3875 | K29: =K28+$H29 -> 0.39097222 | L29: =L28+$H41 -> 0.38333333 | M29: =M28+$H29 -> 0.39791667 | N29: =N28+$H29 -> 0.40138889 | O29: =O28+$H41 -> 0.39375 | P29: =P28+$H29 -> 0.40833333 | Q29: =Q28+$H29 -> 0.41180556 | R29: =R28+$H41 -> 0.40416667 | S29: =S28+$H29 -> 0.41875 | T29: =T28+$H29 -> 0.42222222 | U29: =U28+$H41 -> 0.41458333 | W29: 456 | X29: 3
G30: 제품상차 | H30: 0.010416667 | I30: 제품상차 | J30: =J29+$H30 -> 0.39791667 | K30: =K29+$H30 -> 0.40138889 | L30: =L29+$H42 -> 0.39513889 | M30: =M29+$H30 -> 0.40833333 | N30: =N29+$H30 -> 0.41180556 | O30: =O29+$H42 -> 0.40555556 | P30: =P29+$H30 -> 0.41875 | Q30: =Q29+$H30 -> 0.42222222 | R30: =R29+$H42 -> 0.41597222 | S30: =S29+$H30 -> 0.42916667 | T30: =T29+$H30 -> 0.43263889 | U30: =U29+$H42 -> 0.42638889 | W30: 56 | X30: 34
G31: 이동 | H31: 0.0020833333 | I31: 이동 | J31: =J30+$H31 -> 0.4 | K31: =K30+$H31 -> 0.40347222 | L31: =L30+$H43 -> 0.39791667 | M31: =M30+$H31 -> 0.41041667 | N31: =N30+$H31 -> 0.41388889 | O31: =O30+$H43 -> 0.40833333 | P31: =P30+$H31 -> 0.42083333 | Q31: =Q30+$H31 -> 0.42430556 | R31: =R30+$H43 -> 0.41875 | S31: =S30+$H31 -> 0.43125 | T31: =T30+$H31 -> 0.43472222 | U31: =U30+$H43 -> 0.42916667 | W31: 567 | X31: 4
G32: 선전품상차 | H32: 0.0034722222 | I32: 선전품상차 | J32: =L32+$H32 -> 0.40486111 | K32: =J32+$H32 -> 0.40833333 | L32: =L31+$H44 -> 0.40138889 | M32: =O32+$H32 -> 0.41527778 | N32: =M32+$H32 -> 0.41875 | O32: =O31+$H44 -> 0.41180556 | P32: =R32+$H32 -> 0.42569444 | Q32: =P32+$H32 -> 0.42916667 | R32: =R31+$H44 -> 0.42222222 | S32: =U32+$H32 -> 0.43611111 | T32: =S32+$H32 -> 0.43958333 | U32: =U31+$H44 -> 0.43263889 | W32: 678 | X32: 4
G33: 이동 | H33: 0.0013888889 | I33: 이동 | J33: =J32+$H33 -> 0.40625 | K33: =K32+$H33 -> 0.40972222 | L33: =L32+$H45 -> 0.40208333 | M33: =M32+$H33 -> 0.41666667 | N33: =N32+$H33 -> 0.42013889 | O33: =O32+$H45 -> 0.4125 | P33: =P32+$H33 -> 0.42708333 | Q33: =Q32+$H33 -> 0.43055556 | R33: =R32+$H45 -> 0.42291667 | S33: =S32+$H33 -> 0.4375 | T33: =T32+$H33 -> 0.44097222 | U33: =U32+$H45 -> 0.43333333
G34: CO2 | H34: 0.0034722222 | I34: CO2 | J34: =J33+$H34 -> 0.40972222 | K34: =K33+$H34 -> 0.41319444 | L34: =L33+$H46 -> 0.40486111 | M34: =M33+$H34 -> 0.42013889 | N34: =N33+$H34 -> 0.42361111 | O34: =K34+$H46 -> 0.41597222 | P34: =P33+$H34 -> 0.43055556 | Q34: =Q33+$H34 -> 0.43402778 | R34: =N34+$H46 -> 0.42638889 | S34: =S33+$H34 -> 0.44097222 | T34: =T33+$H34 -> 0.44444444 | U34: =Q34+$H46 -> 0.43680556 | W34: 선전품 순서
G35: 출하캐노피 | H35: 0.0013888889 | I35: 출하캐노피 | J35: =J34+$H35 -> 0.41111111 | K35: =K34+$H35 -> 0.41458333 | L35: =L34+$H47 -> 0.40694444 | M35: =M34+$H35 -> 0.42152778 | N35: =N34+$H35 -> 0.425 | O35: =O34+$H47 -> 0.41805556 | P35: =P34+$H35 -> 0.43194444 | Q35: =Q34+$H35 -> 0.43541667 | R35: =R34+$H47 -> 0.42847222 | S35: =S34+$H35 -> 0.44236111 | T35: =T34+$H35 -> 0.44583333 | U35: =U34+$H47 -> 0.43888889 | X35: 1
G36: 출고검사 및 전표 | H36: 0.0034722222 | I36: 출고검사 및 전표 | J36: =J35+$H36 -> 0.41458333 | K36: =K35+$H36 -> 0.41805556 | L36: =L35+$H48 -> 0.40902778 | M36: =M35+$H36 -> 0.425 | N36: =N35+$H36 -> 0.42847222 | O36: =O35+$H48 -> 0.42013889 | P36: =P35+$H36 -> 0.43541667 | Q36: =Q35+$H36 -> 0.43888889 | R36: =R35+$H48 -> 0.43055556 | S36: =S35+$H36 -> 0.44583333 | T36: =T35+$H36 -> 0.44930556 | U36: =U35+$H48 -> 0.44097222 | W36: 1
I37: 소요시간 | J37: =J36-J25 -> 0.039583333 | K37: =K36-K25 -> 0.039583333 | L37: =L36-L25 -> 0.027083333 | M37: =M36-M25 -> 0.039583333 | N37: =N36-N25 -> 0.039583333 | O37: =O36-O25 -> 0.027777778 | P37: =P36-P25 -> 0.039583333 | Q37: =Q36-Q25 -> 0.039583333 | ... U37: =U36-U25 -> 0.027777778 | W37: 2
G38: 검수(공병하차대기) | H38: 0 | I38: 평균소요시간 | J38: =AVERAGE(J37:U37) -> 0.035590278 | X38: 2
G39: 이동 | H39: 0 | I39: 공차평균소요시간 | J39: =AVERAGE(Q37:T37) -> 0.036631944 | W39: 3
G40: 공병하차 | H40: 0 | I40: 공병평균소요시간 | J40: =AVERAGE(J37:P37,U37) -> 0.035069444 | W40: 4
G41: 이동 | H41: 0.0013888889 | I41: MAX time | J41: =MAX(J37:U37) -> 0.039583333 | X41: 3
G42: 제품상차 | H42: 0.011805556 | I42: MIN time | J42: =MIN(J37:U37) -> 0.027083333 | W42: 5
G43: 이동 | H43: 0.0027777778 | I43: 공차 MAX time | J43: =MAX(Q37:T37) -> 0.039583333 | W43: 6
G44: 선전품상차 | H44: 0.0034722222 | I44: 공차 MIN time | J44: =MIN(Q37:T37) -> 0.027777778 | X44: 4
...

Sheet 동시입차(기존)
I5: 처리 | J5: 동시 | K5: 대당
B6: 기존 | H6: 상차(1h) | I6: 12대 | J6: 4대 | K6: 20분 | Q6: 기존안 | S6: 개선안
B7: 공병트럭 | E7: 공차트럭 | H7: 하차(1h) | I7: 8대 | J7: 1대 | K7: =60/8 -> 7.5 | Q7: 공병 7대 먼저 | S7: 공병+공차 섞어
B8: 입차대기 | C8: 8 | E8: 입차대기 | F8: 12 | Q8: 이후 공차 4대 | S8: 12대
B9: 검수(공병하차대기) | C9: 7 | E9: 검수(공병하차대기) | F9: 0 | Q9: 이후 공병 1대
B10: 이동 | C10: 2 | E10: 이동 | F10: 0 | H10: 배차간격 | I10: 5분
B11: 공병하차 | C11: 6 | E11: 공병하차 | F11: 0 | I11: 이후
B12: 이동 | C12: 3 | E12: 이동 | F12: 2 | I12: 10분
B13: 제품상차 | C13: 7 | E13: 제품상차 | F13: 9
B14: 이동 | C14: 3 | E14: 이동 | F14: 4
B15: 선전품상차 | C15: 5 | E15: 선전품상차 | F15: 5
B16: 이동 | C16: 2 | E16: 이동 | F16: 1
B17: CO2 | C17: 5 | E17: CO2 | F17: 4
B18: 출하캐노피 | C18: 2 | E18: 출하캐노피 | F18: 3
B19: 출고검사 및 전표 | C19: 5 | E19: 출고검사 및 전표 | F19: 3
B20: total | C20: =SUM(C8:C19) -> 55 | E20: total | F20: =SUM(F8:F19) -> 43
B21: 입차대기 제외 | C21: =SUM(C9:C19) -> 47 | E21: 입차대기 제외 | F21: =SUM(F9:F19) -> 31
J23: 끝나는 시간 기준임
J24: 1 | K24: 2 | L24: 3 | M24: 4 | N24: 5 | O24: 6 | P24: 7 | Q24: 1 | R24: 2 | S24: 3 | T24: 4 | U24: 8
I25: 입차 | J25: 0.375 | K25: 0.375 | L25: 0.375 | M25: 0.375 | N25: 0.375 | O25: 0.375 | P25: 0.375 | Q25: 0.375 | R25: 0.375 | S25: 0.375 | T25: 0.375 | U25: 0.375 | W25: 하차 동시에 최대: | X25: 1대
G26: 검수(공병하차대기) | H26: 0.0048611111 | I26: 검수(공병하차대기) | J26: =J25+$H26 -> 0.37986111 | K26: =J26+$H26 -> 0.38472222 | L26: =K26+$H26 -> 0.38958333 | M26: =L26+$H26 -> 0.39444444 | N26: =M26+$H26 -> 0.39930556 | O26: =N26+$H26 -> 0.40416667 | P26: =O26+$H26 -> 0.40902778 | Q26: =P26+$H38 -> 0.41388889 | R26: =Q26+$H38 -> 0.41875 | S26: =R26+$H38 -> 0.42361111 | T26: =S26+$H38 -> 0.42847222 | U26: =T26+$H26 -> 0.43333333 | W26: 상차 동시에 최대: | X26: 3대
G27: 이동 | H27: 0.0013888889 | I27: 이동 | J27: =J26+$H27 -> 0.38125 | K27: =K26+$H27 -> 0.38611111 | L27: =L26+$H27 -> 0.39097222 | M27: =M26+$H27 -> 0.39583333 | N27: =N26+$H27 -> 0.40069444 | O27: =O26+$H27 -> 0.40555556 | P27: =P26+$H27 -> 0.41041667 | Q27: =Q26+$H39 -> 0.41388889 | R27: =R26+$H39 -> 0.41875 | S27: =S26+$H39 -> 0.42361111 | T27: =T26+$H39 -> 0.42847222 | U27: =U26+$H27 -> 0.43472222
G28: 공병하차 | H28: 0.0041666667 | I28: 공병하차 | J28: =J27+$H28 -> 0.38541667 | K28: =K27+$H28 -> 0.39027778 | L28: =L27+$H28 -> 0.39513889 | M28: =M27+$H28 -> 0.4 | N28: =N27+$H28 -> 0.40486111 | O28: =O27+$H28 -> 0.40972222 | P28: =P27+$H28 -> 0.41458333 | Q28: =Q27+$H40 -> 0.41388889 | R28: =R27+$H40 -> 0.41875 | S28: =S27+$H40 -> 0.42361111 | T28: =T27+$H40 -> 0.42847222 | U28: =U27+$H28 -> 0.43888889
G29: 이동 | H29: 0.0020833333 | I29: 이동 | J29: =J28+$H29 -> 0.3875 | K29: =K28+$H29 -> 0.39236111 | L29: =L28+$H29 -> 0.39722222 | M29: =M28+$H29 -> 0.40208333 | N29: =N28+$H29 -> 0.40694444 | O29: =O28+$H29 -> 0.41180556 | P29: =P28+$H29 -> 0.41666667 | Q29: =Q28+$H41 -> 0.41527778 | R29: =R28+$H41 -> 0.42013889 | S29: =S28+$H41 -> 0.425 | T29: =T28+$H41 -> 0.42986111 | U29: =U28+$H29 -> 0.44097222
G30: 제품상차 | H30: 0.0048611111 | I30: 제품상차 | J30: =J29+$H30 -> 0.39236111 | K30: =K29+$H30 -> 0.39722222 | L30: =L29+$H30 -> 0.40208333 | M30: =M29+$H30 -> 0.40694444 | N30: =N29+$H30 -> 0.41180556 | O30: =O29+$H30 -> 0.41666667 | P30: =P29+$H30 -> 0.42152778 | Q30: =Q29+$H42 -> 0.42152778 | R30: =R29+$H42 -> 0.42638889 | S30: =S29+$H42 -> 0.43125 | T30: =T29+$H42 -> 0.43611111 | U30: =U29+$H30 -> 0.44583333
G31: 이동 | H31: 0.0020833333 | I31: 이동 | J31: =J30+$H31 -> 0.39444444 | K31: =K30+$H31 -> 0.39930556 | L31: =L30+$H31 -> 0.40416667 | M31: =M30+$H31 -> 0.40902778 | N31: =N30+$H31 -> 0.41388889 | O31: =O30+$H31 -> 0.41875 | P31: =P30+$H31 -> 0.42361111 | Q31: =Q30+$H43 -> 0.42430556 | R31: =R30+$H43 -> 0.42916667 | S31: =S30+$H43 -> 0.43402778 | T31: =T30+$H43 -> 0.43888889 | U31: =U30+$H31 -> 0.44791667
G32: 선전품상차 | H32: 0.0034722222 | I32: 선전품상차 | J32: =J31+$H32 -> 0.39791667 | K32: =K31+$H32 -> 0.40277778 | L32: =L31+$H32 -> 0.40763889 | M32: =M31+$H32 -> 0.4125 | N32: =N31+$H32 -> 0.41736111 | O32: =O31+$H32 -> 0.42222222 | P32: =P31+$H32 -> 0.42708333 | Q32: =P32+$H44 -> 0.43055556 | R32: =Q32+$H44 -> 0.43402778 | S32: =R32+$H44 -> 0.4375 | T32: =T31+$H44 -> 0.44236111 | U32: =U31+$H32 -> 0.45138889
G33: 이동 | H33: 0.0013888889 | I33: 이동 | J33: =J32+$H33 -> 0.39930556 | K33: =K32+$H33 -> 0.40416667 | L33: =L32+$H33 -> 0.40902778 | M33: =M32+$H33 -> 0.41388889 | N33: =N32+$H33 -> 0.41875 | O33: =O32+$H33 -> 0.42361111 | P33: =P32+$H33 -> 0.42847222 | Q33: =Q32+$H45 -> 0.43125 | R33: =R32+$H45 -> 0.43472222 | S33: =S32+$H45 -> 0.43819444 | T33: =T32+$H45 -> 0.44305556 | U33: =U32+$H33 -> 0.45277778
G34: CO2 | H34: 0.0034722222 | I34: CO2 | J34: =J33+$H34 -> 0.40277778 | K34: =K33+$H34 -> 0.40763889 | L34: =L33+$H34 -> 0.4125 | M34: =M33+$H34 -> 0.41736111 | N34: =N33+$H34 -> 0.42222222 | O34: =O33+$H34 -> 0.42708333 | P34: =P33+$H34 -> 0.43194444 | Q34: =P34+$H46 -> 0.43472222 | R34: =Q34+$H46 -> 0.4375 | S34: =S33+$H46 -> 0.44097222 | T34: =T33+$H46 -> 0.44583333 | U34: =U33+$H34 -> 0.45625
G35: 출하캐노피 | H35: 0.0013888889 | I35: 출하캐노피 | J35: =J34+$H35 -> 0.40416667 | K35: =K34+$H35 -> 0.40902778 | L35: =L34+$H35 -> 0.41388889 | M35: =M34+$H35 -> 0.41875 | N35: =N34+$H35 -> 0.42361111 | O35: =O34+$H35 -> 0.42847222 | P35: =P34+$H35 -> 0.43333333 | Q35: =Q34+$H47 -> 0.43680556 | R35: =R34+$H47 -> 0.43958333 | S35: =S34+$H47 -> 0.44305556 | T35: =T34+$H47 -> 0.44791667 | U35: =U34+$H35 -> 0.45763889
G36: 출고검사 및 전표 | H36: 0.0034722222 | I36: 출고검사 및 전표 | J36: =J35+$H36 -> 0.40763889 | K36: =K35+$H36 -> 0.4125 | L36: =L35+$H36 -> 0.41736111 | M36: =M35+$H36 -> 0.42222222 | N36: =N35+$H36 -> 0.42708333 | O36: =O35+$H36 -> 0.43194444 | P36: =P35+$H36 -> 0.43680556 | Q36: =Q35+$H48 -> 0.43888889 | R36: =R35+$H48 -> 0.44166667 | S36: =S35+$H48 -> 0.44513889 | T36: =T35+$H48 -> 0.45 | U36: =U35+$H36 -> 0.46111111
G38: 검수(공병하차대기) | H38: 0.0048611111
G39: 이동 | H39: 0
G40: 공병하차 | H40: 0
G41: 이동 | H41: 0.0013888889
G42: 제품상차 | H42: 0.00625
G43: 이동 | H43: 0.0027777778
G44: 선전품상차 | H44: 0.0034722222
G45: 이동 | H45: 0.00069444444
G46: CO2 | H46: 0.0027777778
...

Sheet 동시입차(개선)
I5: 처리 | J5: 동시 | K5: 대당
B6: 개선 : 공차 공병하차 대기 제외 | H6: 상차(1h) | I6: 12대 | J6: 4대 | K6: 20분 | Q6: 기존안 | S6: 개선안
B7: 공병트럭 | E7: 공차트럭 | H7: 하차(1h) | I7: 8대 | J7: 1대 | K7: =60/8 -> 7.5 | Q7: 공병 7대 먼저 | S7: 공병+공차 섞어
B8: 입차대기 | C8: 8 | E8: 입차대기 | F8: 12 | Q8: 이후 공차 4대 | S8: 12대
B9: 검수(공병하차대기) | C9: 7 | E9: 검수(공병하차대기) | F9: 0 | Q9: 이후 공병 1대
B10: 이동 | C10: 2 | E10: 이동 | F10: 0 | H10: 배차간격 | I10: 5분
B11: 공병하차 | C11: 6 | E11: 공병하차 | F11: 0 | I11: 이후
B12: 이동 | C12: 3 | E12: 이동 | F12: 2 | I12: 10분
B13: 제품상차 | C13: 7 | E13: 제품상차 | F13: 9
B14: 이동 | C14: 3 | E14: 이동 | F14: 4
B15: 선전품상차 | C15: 5 | E15: 선전품상차 | F15: 5
B16: 이동 | C16: 2 | E16: 이동 | F16: 1
B17: CO2 | C17: 5 | E17: CO2 | F17: 4
B18: 출하캐노피 | C18: 2 | E18: 출하캐노피 | F18: 3
B19: 출고검사 및 전표 | C19: 5 | E19: 출고검사 및 전표 | F19: 3
B20: total | C20: =SUM(C8:C19) -> 55 | E20: total | F20: =SUM(F8:F19) -> 43
B21: 입차대기 제외 | C21: =SUM(C9:C19) -> 47 | E21: 입차대기 제외 | F21: =SUM(F9:F19) -> 31
J23: 끝나는 시간 기준임
J24: 1 | K24: 2 | L24: 3 | M24: 4 | N24: 5 | O24: 6 | P24: 7 | Q24: 1 | R24: 2 | S24: 3 | T24: 4 | U24: 1
I25: 입차 | J25: 0.375 | K25: 0.375 | L25: 0.375 | M25: 0.375 | N25: 0.375 | O25: 0.375 | P25: 0.375 | Q25: 0.375 | R25: 0.375 | S25: 0.375 | T25: 0.375 | U25: 0.375 | W25: 하차 동시에 최대: | X25: 1대
G26: 검수(공병하차대기) | H26: 0.0048611111 | I26: 검수(공병하차대기) | J26: =J25+$H26 -> 0.37986111 | K26: =J26+$H26 -> 0.38472222 | L26: =K26+$H26 -> 0.38958333 | M26: =L26+$H26 -> 0.39444444 | N26: =M26+$H26 -> 0.39930556 | O26: =N26+$H26 -> 0.40416667 | P26: =O26+$H26 -> 0.40902778 | Q26: =Q25+$H38 -> 0.375 | R26: =R25+$H38 -> 0.375 | S26: =S25+$H38 -> 0.375 | T26: =T25+$H38 -> 0.375 | U26: =P26+$H26 -> 0.41388889 | W26: 상차 동시에 최대: | X26: 4대
G27: 이동 | H27: 0.0013888889 | I27: 이동 | J27: =J26+$H27 -> 0.38125 | K27: =K26+$H27 -> 0.38611111 | L27: =L26+$H27 -> 0.39097222 | M27: =M26+$H27 -> 0.39583333 | N27: =N26+$H27 -> 0.40069444 | O27: =O26+$H27 -> 0.40555556 | P27: =P26+$H27 -> 0.41041667 | Q27: =Q26+$H39 -> 0.375 | R27: =R26+$H39 -> 0.375 | S27: =S26+$H39 -> 0.375 | T27: =T26+$H39 -> 0.375 | U27: =U26+$H27 -> 0.41527778
G28: 공병하차 | H28: 0.0041666667 | I28: 공병하차 | J28: =J27+$H28 -> 0.38541667 | K28: =K27+$H28 -> 0.39027778 | L28: =L27+$H28 -> 0.39513889 | M28: =M27+$H28 -> 0.4 | N28: =N27+$H28 -> 0.40486111 | O28: =O27+$H28 -> 0.40972222 | P28: =P27+$H28 -> 0.41458333 | Q28: =Q27+$H40 -> 0.375 | R28: =R27+$H40 -> 0.375 | S28: =S27+$H40 -> 0.375 | T28: =T27+$H40 -> 0.375 | U28: =U27+$H28 -> 0.41944444
G29: 이동 | H29: 0.0020833333 | I29: 이동 | J29: =J28+$H29 -> 0.3875 | K29: =K28+$H29 -> 0.39236111 | L29: =L28+$H29 -> 0.39722222 | M29: =M28+$H29 -> 0.40208333 | N29: =N28+$H29 -> 0.40694444 | O29: =O28+$H29 -> 0.41180556 | P29: =P28+$H29 -> 0.41666667 | Q29: =Q28+$H41 -> 0.37638889 | R29: =R28+$H41 -> 0.37638889 | S29: =S28+$H41 -> 0.37638889 | T29: =T28+$H41 -> 0.37638889 | U29: =U28+$H29 -> 0.42152778
G30: 제품상차 | H30: 0.0048611111 | I30: 제품상차 | J30: =J29+$H30 -> 0.39236111 | K30: =K29+$H30 -> 0.39722222 | L30: =L29+$H30 -> 0.40208333 | M30: =M29+$H30 -> 0.40694444 | N30: =N29+$H30 -> 0.41180556 | O30: =O29+$H30 -> 0.41666667 | P30: =P29+$H30 -> 0.42152778 | Q30: =Q29+$H42 -> 0.38263889 | R30: =R29+$H42 -> 0.38263889 | S30: =S29+$H42 -> 0.38263889 | T30: =T29+$H42 -> 0.38263889 | U30: =U29+$H30 -> 0.42638889
G31: 이동 | H31: 0.0020833333 | I31: 이동 | J31: =J30+$H31 -> 0.39444444 | K31: =K30+$H31 -> 0.39930556 | L31: =L30+$H31 -> 0.40416667 | M31: =M30+$H31 -> 0.40902778 | N31: =N30+$H31 -> 0.41388889 | O31: =O30+$H31 -> 0.41875 | P31: =P30+$H31 -> 0.42361111 | Q31: =Q30+$H43 -> 0.38541667 | R31: =R30+$H43 -> 0.38541667 | S31: =S30+$H43 -> 0.38541667 | T31: =T30+$H43 -> 0.38541667 | U31: =U30+$H31 -> 0.42847222
G32: 선전품상차 | H32: 0.0034722222 | I32: 선전품상차 | J32: =T32+$H32 -> 0.40277778 | K32: =J32+$H32 -> 0.40625 | L32: =K32+$H32 -> 0.40972222 | M32: =L32+$H32 -> 0.41319444 | N32: =N31+$H32 -> 0.41736111 | O32: =O31+$H32 -> 0.42222222 | P32: =P31+$H32 -> 0.42708333 | Q32: =Q31+$H44 -> 0.38888889 | R32: =Q32+$H44 -> 0.39236111 | S32: =R32+$H44 -> 0.39583333 | T32: =S32+$H44 -> 0.39930556 | U32: =U31+$H32 -> 0.43194444
G33: 이동 | H33: 0.0013888889 | I33: 이동 | J33: =J32+$H33 -> 0.40416667 | K33: =K32+$H33 -> 0.40763889 | L33: =L32+$H33 -> 0.41111111 | M33: =M32+$H33 -> 0.41458333 | N33: =N32+$H33 -> 0.41875 | O33: =O32+$H33 -> 0.42361111 | P33: =P32+$H33 -> 0.42847222 | Q33: =Q32+$H45 -> 0.38958333 | R33: =R32+$H45 -> 0.39305556 | S33: =S32+$H45 -> 0.39652778 | T33: =T32+$H45 -> 0.4 | U33: =U32+$H33 -> 0.43333333
G34: CO2 | H34: 0.0034722222 | I34: CO2 | J34: =J33+$H34 -> 0.40763889 | K34: =K33+$H34 -> 0.41111111 | L34: =L33+$H34 -> 0.41458333 | M34: =M33+$H34 -> 0.41805556 | N34: =N33+$H34 -> 0.42222222 | O34: =O33+$H34 -> 0.42708333 | P34: =P33+$H34 -> 0.43194444 | Q34: =Q33+$H46 -> 0.39236111 | R34: =R33+$H46 -> 0.39583333 | S34: =S33+$H46 -> 0.39930556 | T34: =T33+$H46 -> 0.40277778 | U34: =U33+$H34 -> 0.43680556
G35: 출하캐노피 | H35: 0.0013888889 | I35: 출하캐노피 | J35: =J34+$H35 -> 0.40902778 | K35: =K34+$H35 -> 0.4125 | L35: =L34+$H35 -> 0.41597222 | M35: =M34+$H35 -> 0.41944444 | N35: =N34+$H35 -> 0.42361111 | O35: =O34+$H35 -> 0.42847222 | P35: =P34+$H35 -> 0.43333333 | Q35: =Q34+$H47 -> 0.39444444 | R35: =R34+$H47 -> 0.39791667 | S35: =S34+$H47 -> 0.40138889 | T35: =T34+$H47 -> 0.40486111 | U35: =U34+$H35 -> 0.43819444
G36: 출고검사 및 전표 | H36: 0.0034722222 | I36: 출고검사 및 전표 | J36: =J35+$H36 -> 0.4125 | K36: =K35+$H36 -> 0.41597222 | L36: =L35+$H36 -> 0.41944444 | M36: =M35+$H36 -> 0.42291667 | N36: =N35+$H36 -> 0.42708333 | O36: =O35+$H36 -> 0.43194444 | P36: =P35+$H36 -> 0.43680556 | Q36: =Q35+$H48 -> 0.39652778 | R36: =R35+$H48 -> 0.4 | S36: =S35+$H48 -> 0.40347222 | T36: =T35+$H48 -> 0.40694444 | U36: =U35+$H36 -> 0.44166667
G38: 검수(공병하차대기) | H38: 0
G39: 이동 | H39: 0
G40: 공병하차 | H40: 0
G41: 이동 | H41: 0.0013888889
G42: 제품상차 | H42: 0.00625
G43: 이동 | H43: 0.0027777778
G44: 선전품상차 | H44: 0.0034722222
G45: 이동 | H45: 0.00069444444
G46: CO2 | H46: 0.0027777778
...

Sheet 동시입차(개선2)
I5: 처리 | J5: 동시 | K5: 대당
B6: 개선 : 공차 공병하차 대기 제외+순서변경 | H6: 상차(1h) | I6: 12대 | J6: 4대 | K6: 20분 | Q6: 기존안 | S6: 개선안
B7: 공병트럭 | E7: 공차트럭 | H7: 하차(1h) | I7: 8대 | J7: 1대 | K7: =60/8 -> 7.5 | Q7: 공병 7대 먼저 | S7: 공병+공차 섞어
B8: 입차대기 | C8: 8 | E8: 입차대기 | F8: 12 | Q8: 이후 공차 4대 | S8: 12대
B9: 검수(공병하차대기) | C9: 7 | E9: 검수(공병하차대기) | F9: 0 | Q9: 이후 공병 1대
B10: 이동 | C10: 2 | E10: 이동 | F10: 0 | H10: 배차간격 | I10: 5분
B11: 공병하차 | C11: 6 | E11: 공병하차 | F11: 0 | I11: 이후
B12: 이동 | C12: 3 | E12: 이동 | F12: 2 | I12: 10분
B13: 제품상차 | C13: 7 | E13: 제품상차 | F13: 9
B14: 이동 | C14: 3 | E14: 이동 | F14: 4
B15: 선전품상차 | C15: 5 | E15: 선전품상차 | F15: 5
B16: 이동 | C16: 2 | E16: 이동 | F16: 1
B17: CO2 | C17: 5 | E17: CO2 | F17: 4
B18: 출하캐노피 | C18: 2 | E18: 출하캐노피 | F18: 3
B19: 출고검사 및 전표 | C19: 5 | E19: 출고검사 및 전표 | F19: 3
B20: total | C20: =SUM(C8:C19) -> 55 | E20: total | F20: =SUM(F8:F19) -> 43
B21: 입차대기 제외 | C21: =SUM(C9:C19) -> 47 | E21: 입차대기 제외 | F21: =SUM(F9:F19) -> 31
J23: 끝나는 시간 기준임
J24: 1 | K24: 2 | L24: 1 | M24: 3 | N24: 4 | O24: 2 | P24: 5 | Q24: 6 | R24: 3 | S24: 7 | T24: 8 | U24: 4
I25: 입차 | J25: 0.375 | K25: 0.375 | L25: 0.375 | M25: 0.375 | N25: 0.375 | O25: 0.375 | P25: 0.375 | Q25: 0.375 | R25: 0.375 | S25: 0.375 | T25: 0.375 | U25: 0.375 | X25: 하차 동시에 최대: | Z25: 1
G26: 검수(공병하차대기) | H26: 0.0048611111 | I26: 검수(공병하차대기) | J26: =J25+$H26 -> 0.37986111 | K26: =J26+$H26 -> 0.38472222 | L26: =L25+$H38 -> 0.375 | M26: =K26+$H26 -> 0.38958333 | N26: =M26+$H26 -> 0.39444444 | O26: =O25+$H38 -> 0.375 | P26: =N26+$H26 -> 0.39930556 | Q26: =P26+$H26 -> 0.40416667 | R26: =R25+$H38 -> 0.375 | S26: =Q26+$H26 -> 0.40902778 | T26: =S26+$H26 -> 0.41388889 | U26: =U25+$H38 -> 0.375 | X26: 상차 동시에 최대: | Z26: 4
G27: 이동 | H27: 0.0013888889 | I27: 이동 | J27: =J26+$H27 -> 0.38125 | K27: =K26+$H27 -> 0.38611111 | L27: =L26+$H39 -> 0.375 | M27: =M26+$H27 -> 0.39097222 | N27: =N26+$H27 -> 0.39583333 | O27: =O26+$H39 -> 0.375 | P27: =P26+$H27 -> 0.40069444 | Q27: =Q26+$H27 -> 0.40555556 | R27: =R26+$H39 -> 0.375 | S27: =S26+$H27 -> 0.41041667 | T27: =T26+$H27 -> 0.41527778 | U27: =U26+$H39 -> 0.375
G28: 공병하차 | H28: 0.0041666667 | I28: 공병하차 | J28: =J27+$H28 -> 0.38541667 | K28: =K27+$H28 -> 0.39027778 | L28: =L27+$H40 -> 0.375 | M28: =M27+$H28 -> 0.39513889 | N28: =N27+$H28 -> 0.4 | O28: =O27+$H40 -> 0.375 | P28: =P27+$H28 -> 0.40486111 | Q28: =Q27+$H28 -> 0.40972222 | R28: =R27+$H40 -> 0.375 | S28: =S27+$H28 -> 0.41458333 | T28: =T27+$H28 -> 0.41944444 | U28: =U27+$H40 -> 0.375
G29: 이동 | H29: 0.0020833333 | I29: 이동 | J29: =J28+$H29 -> 0.3875 | K29: =K28+$H29 -> 0.39236111 | L29: =L28+$H41 -> 0.37638889 | M29: =M28+$H29 -> 0.39722222 | N29: =N28+$H29 -> 0.40208333 | O29: =O28+$H41 -> 0.37638889 | P29: =P28+$H29 -> 0.40694444 | Q29: =Q28+$H29 -> 0.41180556 | R29: =R28+$H41 -> 0.37638889 | S29: =S28+$H29 -> 0.41666667 | T29: =T28+$H29 -> 0.42152778 | U29: =U28+$H41 -> 0.37638889
G30: 제품상차 | H30: 0.0048611111 | I30: 제품상차 | J30: =J29+$H30 -> 0.39236111 | K30: =K29+$H30 -> 0.39722222 | L30: =L29+$H42 -> 0.38263889 | M30: =M29+$H30 -> 0.40208333 | N30: =N29+$H30 -> 0.40694444 | O30: =O29+$H42 -> 0.38263889 | P30: =P29+$H30 -> 0.41180556 | Q30: =Q29+$H30 -> 0.41666667 | R30: =R29+$H42 -> 0.38263889 | S30: =S29+$H30 -> 0.42152778 | T30: =T29+$H30 -> 0.42638889 | U30: =U29+$H42 -> 0.38263889
G31: 이동 | H31: 0.0020833333 | I31: 이동 | J31: =J30+$H31 -> 0.39444444 | K31: =K30+$H31 -> 0.39930556 | L31: =L30+$H43 -> 0.38541667 | M31: =M30+$H31 -> 0.40416667 | N31: =N30+$H31 -> 0.40902778 | O31: =O30+$H43 -> 0.38541667 | P31: =P30+$H31 -> 0.41388889 | Q31: =Q30+$H31 -> 0.41875 | R31: =R30+$H43 -> 0.38541667 | S31: =S30+$H31 -> 0.42361111 | T31: =T30+$H31 -> 0.42847222 | U31: =U30+$H43 -> 0.38541667
G32: 선전품상차 | H32: 0.0034722222 | I32: 선전품상차 | J32: =U32+$H32 -> 0.40277778 | K32: =J32+$H32 -> 0.40625 | L32: =L31+$H44 -> 0.38888889 | M32: =K32+$H32 -> 0.40972222 | N32: =M32+$H32 -> 0.41319444 | O32: =L32+$H44 -> 0.39236111 | P32: =P31+$H32 -> 0.41736111 | Q32: =Q31+$H32 -> 0.42222222 | R32: =O32+$H44 -> 0.39583333 | S32: =S31+$H32 -> 0.42708333 | T32: =T31+$H32 -> 0.43194444 | U32: =R32+$H44 -> 0.39930556
G33: 이동 | H33: 0.0013888889 | I33: 이동 | J33: =J32+$H33 -> 0.40416667 | K33: =K32+$H33 -> 0.40763889 | L33: =L32+$H45 -> 0.38958333 | M33: =M32+$H33 -> 0.41111111 | N33: =N32+$H33 -> 0.41458333 | O33: =O32+$H45 -> 0.39305556 | P33: =P32+$H33 -> 0.41875 | Q33: =Q32+$H33 -> 0.42361111 | R33: =R32+$H45 -> 0.39652778 | S33: =S32+$H33 -> 0.42847222 | T33: =T32+$H33 -> 0.43333333 | U33: =U32+$H45 -> 0.4
G34: CO2 | H34: 0.0034722222 | I34: CO2 | J34: =J33+$H34 -> 0.40763889 | K34: =K33+$H34 -> 0.41111111 | L34: =L33+$H46 -> 0.39236111 | M34: =M33+$H34 -> 0.41458333 | N34: =N33+$H34 -> 0.41805556 | O34: =O33+$H46 -> 0.39583333 | P34: =P33+$H34 -> 0.42222222 | Q34: =Q33+$H34 -> 0.42708333 | R34: =R33+$H46 -> 0.39930556 | S34: =S33+$H34 -> 0.43194444 | T34: =T33+$H34 -> 0.43680556 | U34: =U33+$H46 -> 0.40277778
G35: 출하캐노피 | H35: 0.0013888889 | I35: 출하캐노피 | J35: =J34+$H35 -> 0.40902778 | K35: =K34+$H35 -> 0.4125 | L35: =L34+$H47 -> 0.39444444 | M35: =M34+$H35 -> 0.41597222 | N35: =N34+$H35 -> 0.41944444 | O35: =O34+$H47 -> 0.39791667 | P35: =P34+$H35 -> 0.42361111 | Q35: =Q34+$H35 -> 0.42847222 | R35: =R34+$H47 -> 0.40138889 | S35: =S34+$H35 -> 0.43333333 | T35: =T34+$H35 -> 0.43819444 | U35: =U34+$H47 -> 0.40486111
G36: 출고검사 및 전표 | H36: 0.0034722222 | I36: 출고검사 및 전표 | J36: =J35+$H36 -> 0.4125 | K36: =K35+$H36 -> 0.41597222 | L36: =L35+$H48 -> 0.39652778 | M36: =M35+$H36 -> 0.41944444 | N36: =N35+$H36 -> 0.42291667 | O36: =O35+$H48 -> 0.4 | P36: =P35+$H36 -> 0.42708333 | Q36: =Q35+$H36 -> 0.43194444 | R36: =R35+$H48 -> 0.40347222 | S36: =S35+$H36 -> 0.43680556 | T36: =T35+$H36 -> 0.44166667 | U36: =U35+$H48 -> 0.40694444
G38: 검수(공병하차대기) | H38: 0
G39: 이동 | H39: 0
G40: 공병하차 | H40: 0
G41: 이동 | H41: 0.0013888889
G42: 제품상차 | H42: 0.00625
G43: 이동 | H43: 0.0027777778
G44: 선전품상차 | H44: 0.0034722222
G45: 이동 | H45: 0.00069444444
G46: CO2 | H46: 0.0027777778
...
